Workbook

Sheet Concealed
A1: Concealed fan coil database: one row per model, add new brands/models in the empty rows below the example (up to row 305)
A2: Enter all capacities at the same rating conditions for every model (e.g., chilled water 7/12 °C, hot water 45/40 °C). Brand names must be spelled identically on every row. The row marked EXAMPLE is ignored.
C4: Low speed | G4: Medium speed | K4: High speed
A5: Brand | B5: Model | C5: Total Cooling (BTU/hr) | D5: Sensible Cooling (BTU/hr) | E5: Heating (BTU/hr) | F5: Airflow (CFM) | G5: Total Cooling (BTU/hr) | H5: Sensible Cooling (BTU/hr) | I5: Heating (BTU/hr) | J5: Airflow (CFM) | K5: Total Cooling (BTU/hr) | L5: Sensible Cooling (BTU/hr) | M5: Heating (BTU/hr) | N5: Airflow (CFM) | O5: Notes / Source
A6: EXAMPLE | B6: Model-XXX | C6: 9000 | D6: 6500 | E6: 12000 | F6: 300 | G6: 8000 | H6: 5800 | I6: 11000 | J6: 250 | K6: 6500 | L6: 4800 | M6: 9500 | N6: 200 | O6: Illustrative only – ignored
A7: تهویه | B7: HR/HS 200 | C7: 3105 | D7: 2525 | E7: 3856 | F7: 96 | G7: 3719 | H7: 3037 | I7: 4606 | J7: 120 | K7: 5528 | L7: 4572 | M7: 6688 | N7: 200 | O7: HR/HS series (ceiling concealed); catalog kW × 3412.14, CFM from catalog
A8: تهویه | B8: HR/HS 300 | C8: 6722 | D8: 4743 | E8: 6995 | F8: 142 | G8: 9998 | H8: 6893 | I8: 9929 | J8: 213 | K8: 13103 | L8: 9179 | M8: 13171 | N8: 300 | O8: HR/HS series (ceiling concealed); catalog kW × 3412.14, CFM from catalog
A9: تهویه | B9: HR/HS 400 | C9: 8189 | D9: 5971 | E9: 8803 | F9: 195 | G9: 12250 | H9: 8872 | I9: 12830 | J9: 310 | K9: 14706 | L9: 10816 | M9: 15593 | N9: 400 | O9: HR/HS series (ceiling concealed); catalog kW × 3412.14, CFM from catalog
A10: تهویه | B10: HR/HS 600 | C10: 15901 | D10: 11124 | E10: 15832 | F10: 360 | G10: 20098 | H10: 14331 | I10: 20336 | J10: 498 | K10: 22725 | L10: 16344 | M10: 23305 | N10: 600 | O10: HR/HS series (ceiling concealed); catalog kW × 3412.14, CFM from catalog
A11: تهویه | B11: HR/HS 800 | C11: 19176 | D11: 10782 | E11: 16276 | F11: 444 | G11: 24294 | H11: 13922 | I11: 21292 | J11: 617 | K11: 28764 | L11: 16719 | M11: 25966 | N11: 800 | O11: HR/HS series (ceiling concealed); catalog kW × 3412.14, CFM from catalog
A12: تهویه | B12: HR/HS 1000 | C12: 27468 | D12: 15321 | E12: 22998 | F12: 612 | G12: 33132 | H12: 18801 | I12: 28423 | J12: 788 | K12: 39205 | L12: 22486 | M12: 34360 | N12: 1000 | O12: HR/HS series (ceiling concealed); catalog kW × 3412.14, CFM from catalog
A13: تهویه | B13: HR/HS 1200 | C13: 30709 | D13: 17334 | E13: 26137 | F13: 712 | G13: 37397 | H13: 21360 | I13: 32518 | J13: 932 | K13: 44358 | L13: 25591 | M13: 39547 | N13: 1200 | O13: HR/HS series (ceiling concealed); catalog kW × 3412.14, CFM from catalog

Sheet Ducted
A1: Ducted fan coil database: one row per model, add new brands/models in the empty rows below the example (up to row 305)
A2: Enter all capacities at the same rating conditions for every model (e.g., chilled water 7/12 °C, hot water 45/40 °C). Brand names must be spelled identically on every row. The row marked EXAMPLE is ignored.
C4: Low speed | G4: Medium speed | K4: High speed
A5: Brand | B5: Model | C5: Total Cooling (BTU/hr) | D5: Sensible Cooling (BTU/hr) | E5: Heating (BTU/hr) | F5: Airflow (CFM) | G5: Total Cooling (BTU/hr) | H5: Sensible Cooling (BTU/hr) | I5: Heating (BTU/hr) | J5: Airflow (CFM) | K5: Total Cooling (BTU/hr) | L5: Sensible Cooling (BTU/hr) | M5: Heating (BTU/hr) | N5: Airflow (CFM) | O5: Notes / Source
A6: EXAMPLE | B6: Model-XXX | C6: 9000 | D6: 6500 | E6: 12000 | F6: 300 | G6: 8000 | H6: 5800 | I6: 11000 | J6: 250 | K6: 6500 | L6: 4800 | M6: 9500 | N6: 200 | O6: Illustrative only – ignored
A7: تهویه | B7: AR N-06 | C7: 15013 | D7: 10919 | E7: 15355 | F7: 384 | G7: 17743 | H7: 12966 | I7: 18084 | J7: 480 | K7: 20473 | L7: 15355 | M7: 21155 | N7: 600 | O7: AR N series (slim ducted); catalog kW × 3412.14, CFM from catalog
A8: تهویه | B8: AR N-08 | C8: 18426 | D8: 13649 | E8: 18767 | F8: 512 | G8: 21496 | H8: 16037 | I8: 22179 | J8: 640 | K8: 24909 | L8: 18426 | M8: 25591 | N8: 800 | O8: AR N series (slim ducted); catalog kW × 3412.14, CFM from catalog
A9: تهویه | B9: AR N-10 | C9: 26615 | D9: 18767 | E9: 26615 | F9: 640 | G9: 31050 | H9: 22520 | I9: 31392 | J9: 800 | K9: 36169 | L9: 26273 | M9: 36851 | N9: 1000 | O9: AR N series (slim ducted); catalog kW × 3412.14, CFM from catalog
A10: تهویه | B10: AR N-12 | C10: 26956 | D10: 20132 | E10: 29003 | F10: 768 | G10: 32074 | H10: 23885 | I10: 34121 | J10: 960 | K10: 37875 | L10: 28321 | M10: 39922 | N10: 1200 | O10: AR N series (slim ducted); catalog kW × 3412.14, CFM from catalog
A11: تهویه | B11: AR N-14 | C11: 31050 | D11: 22861 | E11: 32415 | F11: 896 | G11: 35827 | H11: 26956 | I11: 38216 | J11: 1120 | K11: 40946 | L11: 31050 | M11: 44358 | N11: 1400 | O11: AR N series (slim ducted); catalog kW × 3412.14, CFM from catalog
A12: تهویه | B12: AR N-16 | C12: 33780 | D12: 25250 | E12: 35827 | F12: 1024 | G12: 38898 | H12: 29344 | I12: 41969 | J12: 1280 | K12: 44699 | L12: 34121 | M12: 48452 | N12: 1600 | O12: AR N series (slim ducted); catalog kW × 3412.14, CFM from catalog
A13: تهویه | B13: AR N-18 | C13: 46746 | D13: 33439 | E13: 48452 | F13: 1152 | G13: 55277 | H13: 39922 | I13: 57665 | J13: 1440 | K13: 64489 | L13: 47088 | M13: 68584 | N13: 1800 | O13: AR N series (slim ducted); catalog kW × 3412.14, CFM from catalog
A14: تهویه | B14: AR N-20 | C14: 50158 | D14: 36169 | E14: 52888 | F14: 1280 | G14: 59371 | H14: 43334 | I14: 62442 | J14: 1600 | K14: 70290 | L14: 51523 | M14: 73702 | N14: 2000 | O14: AR N series (slim ducted); catalog kW × 3412.14, CFM from catalog
A15: تهویه | B15: AR N-23 | C15: 55959 | D15: 40741 | E15: 58689 | F15: 1472 | G15: 65718 | H15: 48214 | I15: 69608 | J15: 1840 | K15: 76261 | L15: 56334 | M15: 81209 | N15: 2300 | O15: AR N series (slim ducted); catalog kW × 3412.14, CFM from catalog

Sheet Cassette
A1: Cassette fan coil database: one row per model, add new brands/models in the empty rows below the example (up to row 305)
A2: Enter all capacities at the same rating conditions for every model (e.g., chilled water 7/12 °C, hot water 45/40 °C). Brand names must be spelled identically on every row. The row marked EXAMPLE is ignored.
C4: Low speed | G4: Medium speed | K4: High speed
A5: Brand | B5: Model | C5: Total Cooling (BTU/hr) | D5: Sensible Cooling (BTU/hr) | E5: Heating (BTU/hr) | F5: Airflow (CFM) | G5: Total Cooling (BTU/hr) | H5: Sensible Cooling (BTU/hr) | I5: Heating (BTU/hr) | J5: Airflow (CFM) | K5: Total Cooling (BTU/hr) | L5: Sensible Cooling (BTU/hr) | M5: Heating (BTU/hr) | N5: Airflow (CFM) | O5: Notes / Source
A6: EXAMPLE | B6: Model-XXX | C6: 9000 | D6: 6500 | E6: 12000 | F6: 300 | G6: 8000 | H6: 5800 | I6: 11000 | J6: 250 | K6: 6500 | L6: 4800 | M6: 9500 | N6: 200 | O6: Illustrative only – ignored

Sheet Brands
A1: All brand cells (auto) | B1: Unique # | D1: Brand list (auto – do not edit)
A2: =IF(Concealed!A7="","",TRIM(Concealed!A7)) -> تهویه | B2: =IF(A2="","",IF(COUNTIF(A$2:A2,A2)=1,MAX(B$1:B1)+1,"")) -> 1 | D2: =IFERROR(INDEX($A$2:$A$901,MATCH(1,$B$2:$B$901,0)),"") -> تهویه
A3: =IF(Concealed!A8="","",TRIM(Concealed!A8)) -> تهویه | B3: =IF(A3="","",IF(COUNTIF(A$2:A3,A3)=1,MAX(B$1:B2)+1,"")) | D3: =IFERROR(INDEX($A$2:$A$901,MATCH(2,$B$2:$B$901,0)),"")
A4: =IF(Concealed!A9="","",TRIM(Concealed!A9)) -> تهویه | B4: =IF(A4="","",IF(COUNTIF(A$2:A4,A4)=1,MAX(B$1:B3)+1,"")) | D4: =IFERROR(INDEX($A$2:$A$901,MATCH(3,$B$2:$B$901,0)),"")
A5: =IF(Concealed!A10="","",TRIM(Concealed!A10)) -> تهویه | B5: =IF(A5="","",IF(COUNTIF(A$2:A5,A5)=1,MAX(B$1:B4)+1,"")) | D5: =IFERROR(INDEX($A$2:$A$901,MATCH(4,$B$2:$B$901,0)),"")
A6: =IF(Concealed!A11="","",TRIM(Concealed!A11)) -> تهویه | B6: =IF(A6="","",IF(COUNTIF(A$2:A6,A6)=1,MAX(B$1:B5)+1,"")) | D6: =IFERROR(INDEX($A$2:$A$901,MATCH(5,$B$2:$B$901,0)),"")
A7: =IF(Concealed!A12="","",TRIM(Concealed!A12)) -> تهویه | B7: =IF(A7="","",IF(COUNTIF(A$2:A7,A7)=1,MAX(B$1:B6)+1,"")) | D7: =IFERROR(INDEX($A$2:$A$901,MATCH(6,$B$2:$B$901,0)),"")
A8: =IF(Concealed!A13="","",TRIM(Concealed!A13)) -> تهویه | B8: =IF(A8="","",IF(COUNTIF(A$2:A8,A8)=1,MAX(B$1:B7)+1,"")) | D8: =IFERROR(INDEX($A$2:$A$901,MATCH(7,$B$2:$B$901,0)),"")
A9: =IF(Concealed!A14="","",TRIM(Concealed!A14)) | B9: =IF(A9="","",IF(COUNTIF(A$2:A9,A9)=1,MAX(B$1:B8)+1,"")) | D9: =IFERROR(INDEX($A$2:$A$901,MATCH(8,$B$2:$B$901,0)),"")
A10: =IF(Concealed!A15="","",TRIM(Concealed!A15)) | B10: =IF(A10="","",IF(COUNTIF(A$2:A10,A10)=1,MAX(B$1:B9)+1,"")) | D10: =IFERROR(INDEX($A$2:$A$901,MATCH(9,$B$2:$B$901,0)),"")
A11: =IF(Concealed!A16="","",TRIM(Concealed!A16)) | B11: =IF(A11="","",IF(COUNTIF(A$2:A11,A11)=1,MAX(B$1:B10)+1,"")) | D11: =IFERROR(INDEX($A$2:$A$901,MATCH(10,$B$2:$B$901,0)),"")
A12: =IF(Concealed!A17="","",TRIM(Concealed!A17)) | B12: =IF(A12="","",IF(COUNTIF(A$2:A12,A12)=1,MAX(B$1:B11)+1,"")) | D12: =IFERROR(INDEX($A$2:$A$901,MATCH(11,$B$2:$B$901,0)),"")
A13: =IF(Concealed!A18="","",TRIM(Concealed!A18)) | B13: =IF(A13="","",IF(COUNTIF(A$2:A13,A13)=1,MAX(B$1:B12)+1,"")) | D13: =IFERROR(INDEX($A$2:$A$901,MATCH(12,$B$2:$B$901,0)),"")
A14: =IF(Concealed!A19="","",TRIM(Concealed!A19)) | B14: =IF(A14="","",IF(COUNTIF(A$2:A14,A14)=1,MAX(B$1:B13)+1,"")) | D14: =IFERROR(INDEX($A$2:$A$901,MATCH(13,$B$2:$B$901,0)),"")
A15: =IF(Concealed!A20="","",TRIM(Concealed!A20)) | B15: =IF(A15="","",IF(COUNTIF(A$2:A15,A15)=1,MAX(B$1:B14)+1,"")) | D15: =IFERROR(INDEX($A$2:$A$901,MATCH(14,$B$2:$B$901,0)),"")
A16: =IF(Concealed!A21="","",TRIM(Concealed!A21)) | B16: =IF(A16="","",IF(COUNTIF(A$2:A16,A16)=1,MAX(B$1:B15)+1,"")) | D16: =IFERROR(INDEX($A$2:$A$901,MATCH(15,$B$2:$B$901,0)),"")
A17: =IF(Concealed!A22="","",TRIM(Concealed!A22)) | B17: =IF(A17="","",IF(COUNTIF(A$2:A17,A17)=1,MAX(B$1:B16)+1,"")) | D17: =IFERROR(INDEX($A$2:$A$901,MATCH(16,$B$2:$B$901,0)),"")
A18: =IF(Concealed!A23="","",TRIM(Concealed!A23)) | B18: =IF(A18="","",IF(COUNTIF(A$2:A18,A18)=1,MAX(B$1:B17)+1,"")) | D18: =IFERROR(INDEX($A$2:$A$901,MATCH(17,$B$2:$B$901,0)),"")
A19: =IF(Concealed!A24="","",TRIM(Concealed!A24)) | B19: =IF(A19="","",IF(COUNTIF(A$2:A19,A19)=1,MAX(B$1:B18)+1,"")) | D19: =IFERROR(INDEX($A$2:$A$901,MATCH(18,$B$2:$B$901,0)),"")
A20: =IF(Concealed!A25="","",TRIM(Concealed!A25)) | B20: =IF(A20="","",IF(COUNTIF(A$2:A20,A20)=1,MAX(B$1:B19)+1,"")) | D20: =IFERROR(INDEX($A$2:$A$901,MATCH(19,$B$2:$B$901,0)),"")
A21: =IF(Concealed!A26="","",TRIM(Concealed!A26)) | B21: =IF(A21="","",IF(COUNTIF(A$2:A21,A21)=1,MAX(B$1:B20)+1,"")) | D21: =IFERROR(INDEX($A$2:$A$901,MATCH(20,$B$2:$B$901,0)),"")
A22: =IF(Concealed!A27="","",TRIM(Concealed!A27)) | B22: =IF(A22="","",IF(COUNTIF(A$2:A22,A22)=1,MAX(B$1:B21)+1,"")) | D22: =IFERROR(INDEX($A$2:$A$901,MATCH(21,$B$2:$B$901,0)),"")
A23: =IF(Concealed!A28="","",TRIM(Concealed!A28)) | B23: =IF(A23="","",IF(COUNTIF(A$2:A23,A23)=1,MAX(B$1:B22)+1,"")) | D23: =IFERROR(INDEX($A$2:$A$901,MATCH(22,$B$2:$B$901,0)),"")
A24: =IF(Concealed!A29="","",TRIM(Concealed!A29)) | B24: =IF(A24="","",IF(COUNTIF(A$2:A24,A24)=1,MAX(B$1:B23)+1,"")) | D24: =IFERROR(INDEX($A$2:$A$901,MATCH(23,$B$2:$B$901,0)),"")
A25: =IF(Concealed!A30="","",TRIM(Concealed!A30)) | B25: =IF(A25="","",IF(COUNTIF(A$2:A25,A25)=1,MAX(B$1:B24)+1,"")) | D25: =IFERROR(INDEX($A$2:$A$901,MATCH(24,$B$2:$B$901,0)),"")
A26: =IF(Concealed!A31="","",TRIM(Concealed!A31)) | B26: =IF(A26="","",IF(COUNTIF(A$2:A26,A26)=1,MAX(B$1:B25)+1,"")) | D26: =IFERROR(INDEX($A$2:$A$901,MATCH(25,$B$2:$B$901,0)),"")
A27: =IF(Concealed!A32="","",TRIM(Concealed!A32)) | B27: =IF(A27="","",IF(COUNTIF(A$2:A27,A27)=1,MAX(B$1:B26)+1,"")) | D27: =IFERROR(INDEX($A$2:$A$901,MATCH(26,$B$2:$B$901,0)),"")
A28: =IF(Concealed!A33="","",TRIM(Concealed!A33)) | B28: =IF(A28="","",IF(COUNTIF(A$2:A28,A28)=1,MAX(B$1:B27)+1,"")) | D28: =IFERROR(INDEX($A$2:$A$901,MATCH(27,$B$2:$B$901,0)),"")
A29: =IF(Concealed!A34="","",TRIM(Concealed!A34)) | B29: =IF(A29="","",IF(COUNTIF(A$2:A29,A29)=1,MAX(B$1:B28)+1,"")) | D29: =IFERROR(INDEX($A$2:$A$901,MATCH(28,$B$2:$B$901,0)),"")
A30: =IF(Concealed!A35="","",TRIM(Concealed!A35)) | B30: =IF(A30="","",IF(COUNTIF(A$2:A30,A30)=1,MAX(B$1:B29)+1,"")) | D30: =IFERROR(INDEX($A$2:$A$901,MATCH(29,$B$2:$B$901,0)),"")
A31: =IF(Concealed!A36="","",TRIM(Concealed!A36)) | B31: =IF(A31="","",IF(COUNTIF(A$2:A31,A31)=1,MAX(B$1:B30)+1,"")) | D31: =IFERROR(INDEX($A$2:$A$901,MATCH(30,$B$2:$B$901,0)),"")
A32: =IF(Concealed!A37="","",TRIM(Concealed!A37)) | B32: =IF(A32="","",IF(COUNTIF(A$2:A32,A32)=1,MAX(B$1:B31)+1,"")) | D32: =IFERROR(INDEX($A$2:$A$901,MATCH(31,$B$2:$B$901,0)),"")
A33: =IF(Concealed!A38="","",TRIM(Concealed!A38)) | B33: =IF(A33="","",IF(COUNTIF(A$2:A33,A33)=1,MAX(B$1:B32)+1,"")) | D33: =IFERROR(INDEX($A$2:$A$901,MATCH(32,$B$2:$B$901,0)),"")
A34: =IF(Concealed!A39="","",TRIM(Concealed!A39)) | B34: =IF(A34="","",IF(COUNTIF(A$2:A34,A34)=1,MAX(B$1:B33)+1,"")) | D34: =IFERROR(INDEX($A$2:$A$901,MATCH(33,$B$2:$B$901,0)),"")
A35: =IF(Concealed!A40="","",TRIM(Concealed!A40)) | B35: =IF(A35="","",IF(COUNTIF(A$2:A35,A35)=1,MAX(B$1:B34)+1,"")) | D35: =IFERROR(INDEX($A$2:$A$901,MATCH(34,$B$2:$B$901,0)),"")
A36: =IF(Concealed!A41="","",TRIM(Concealed!A41)) | B36: =IF(A36="","",IF(COUNTIF(A$2:A36,A36)=1,MAX(B$1:B35)+1,"")) | D36: =IFERROR(INDEX($A$2:$A$901,MATCH(35,$B$2:$B$901,0)),"")
A37: =IF(Concealed!A42="","",TRIM(Concealed!A42)) | B37: =IF(A37="","",IF(COUNTIF(A$2:A37,A37)=1,MAX(B$1:B36)+1,"")) | D37: =IFERROR(INDEX($A$2:$A$901,MATCH(36,$B$2:$B$901,0)),"")
A38: =IF(Concealed!A43="","",TRIM(Concealed!A43)) | B38: =IF(A38="","",IF(COUNTIF(A$2:A38,A38)=1,MAX(B$1:B37)+1,"")) | D38: =IFERROR(INDEX($A$2:$A$901,MATCH(37,$B$2:$B$901,0)),"")
A39: =IF(Concealed!A44="","",TRIM(Concealed!A44)) | B39: =IF(A39="","",IF(COUNTIF(A$2:A39,A39)=1,MAX(B$1:B38)+1,"")) | D39: =IFERROR(INDEX($A$2:$A$901,MATCH(38,$B$2:$B$901,0)),"")
A40: =IF(Concealed!A45="","",TRIM(Concealed!A45)) | B40: =IF(A40="","",IF(COUNTIF(A$2:A40,A40)=1,MAX(B$1:B39)+1,"")) | D40: =IFERROR(INDEX($A$2:$A$901,MATCH(39,$B$2:$B$901,0)),"")
...
